Workbook
Name Slicer_cnt: #N/A
Name Slicer_dteday: #N/A

Sheet dataset_3
A1: instant | B1: dteday | C1: season | D1: yr | E1: mnth | F1: hr | G1: holiday | H1: weekday | I1: weathersit | J1: temp | K1: atemp | L1: hum | M1: windspeed | N1: casual | O1: registered | P1: cnt
A2: 611 | B2: 40571 | C2: 1 | D2: 0 | E2: 1 | F2: 16 | G2: FALSE | H2: 5 | I2: 1 | J2: 0.22 | K2: 0.2727 | L2: 0.8 | M2: 0 | N2: 10 | O2: 70 | P2: 80
A3: 612 | B3: 40571 | C3: 1 | D3: 0 | E3: 1 | F3: 17 | G3: FALSE | H3: 5 | I3: 1 | J3: 0.24 | K3: 0.2424 | L3: 0.75 | M3: 0.1343 | N3: 2 | O3: 147 | P3: 149
A4: 613 | B4: 40571 | C4: 1 | D4: 0 | E4: 1 | F4: 18 | G4: FALSE | H4: 5 | I4: 1 | J4: 0.24 | K4: 0.2273 | L4: 0.75 | M4: 0.194 | N4: 2 | O4: 107 | P4: 109
A5: 614 | B5: 40571 | C5: 1 | D5: 0 | E5: 1 | F5: 19 | G5: FALSE | H5: 5 | I5: 2 | J5: 0.24 | K5: 0.2424 | L5: 0.75 | M5: 0.1343 | N5: 5 | O5: 84 | P5: 89
A6: 615 | B6: 40571 | C6: 1 | D6: 0 | E6: 1 | F6: 20 | G6: FALSE | H6: 5 | I6: 2 | J6: 0.24 | K6: 0.2273 | L6: 0.7 | M6: 0.194 | N6: 1 | O6: 61 | P6: 62
A7: 616 | B7: 40571 | C7: 1 | D7: 0 | E7: 1 | F7: 21 | G7: FALSE | H7: 5 | I7: 2 | J7: 0.22 | K7: 0.2273 | L7: 0.75 | M7: 0.1343 | N7: 1 | O7: 57 | P7: 58
A8: 617 | B8: 40571 | C8: 1 | D8: 0 | E8: 1 | F8: 22 | G8: FALSE | H8: 5 | I8: 1 | J8: 0.24 | K8: 0.2121 | L8: 0.65 | M8: 0.3582 | N8: 0 | O8: 26 | P8: 26
A9: 618 | B9: 40571 | C9: 1 | D9: 0 | E9: 1 | F9: 23 | G9: FALSE | H9: 5 | I9: 1 | J9: 0.24 | K9: 0.2273 | L9: 0.6 | M9: 0.2239 | N9: 1 | O9: 22 | P9: 23
A10: 619 | B10: 40572 | C10: 1 | D10: 0 | E10: 1 | F10: 0 | G10: FALSE | H10: 6 | I10: 1 | J10: 0.22 | K10: 0.197 | L10: 0.64 | M10: 0.3582 | N10: 2 | O10: 26 | P10: 28
A11: 620 | B11: 40572 | C11: 1 | D11: 0 | E11: 1 | F11: 1 | G11: FALSE | H11: 6 | I11: 1 | J11: 0.22 | K11: 0.2273 | L11: 0.64 | M11: 0.194 | N11: 0 | O11: 20 | P11: 20
A12: 621 | B12: 40572 | C12: 1 | D12: 0 | E12: 1 | F12: 2 | G12: FALSE | H12: 6 | I12: 1 | J12: 0.22 | K12: 0.2273 | L12: 0.64 | M12: 0.1642 | N12: 0 | O12: 15 | P12: 15
A13: 622 | B13: 40572 | C13: 1 | D13: 0 | E13: 1 | F13: 3 | G13: FALSE | H13: 6 | I13: 1 | J13: 0.2 | K13: 0.2121 | L13: 0.64 | M13: 0.1343 | N13: 3 | O13: 5 | P13: 8
... A391: 1000 | B391: 40588 | C391: 1 | D391: 0 | E391: 2 | F391: 7 | G391: FALSE | H391: 1 | I391: 1 | J391: 0.34 | K391: 0.303 | L391: 0.46 | M391: 0.2985 | N391: 2 | O391: 96 | P391: 98

Sheet DATASET 1
A1: instant | B1: dteday | C1: season | D1: yr | E1: mnth | F1: hr | G1: holiday | H1: weekday | I1: weathersit | J1: temp
A2: 1 | B2: 40544 | C2: 1 | D2: 0 | E2: 1 | F2: 0 | G2: FALSE | H2: 6 | I2: 1 | J2: 0.24
A3: 2 | B3: 40544 | C3: 1 | D3: 0 | E3: 1 | F3: 1 | G3: FALSE | H3: 6 | I3: 1 | J3: 0.22
A4: 3 | B4: 40544 | C4: 1 | D4: 0 | E4: 1 | F4: 2 | G4: FALSE | H4: 6 | I4: 1 | J4: 0.22
A5: 4 | B5: 40544 | C5: 1 | D5: 0 | E5: 1 | F5: 3 | G5: FALSE | H5: 6 | I5: 1 | J5: 0.24
A6: 5 | B6: 40544 | C6: 1 | D6: 0 | E6: 1 | F6: 4 | G6: FALSE | H6: 6 | I6: 1 | J6: 0.24
A7: 6 | B7: 40544 | C7: 1 | D7: 0 | E7: 1 | F7: 5 | G7: FALSE | H7: 6 | I7: 2 | J7: 0.24
A8: 7 | B8: 40544 | C8: 1 | D8: 0 | E8: 1 | F8: 6 | G8: FALSE | H8: 6 | I8: 1 | J8: 0.22
A9: 8 | B9: 40544 | C9: 1 | D9: 0 | E9: 1 | F9: 7 | G9: FALSE | H9: 6 | I9: 1 | J9: 0.2
A10: 9 | B10: 40544 | C10: 1 | D10: 0 | E10: 1 | F10: 8 | G10: FALSE | H10: 6 | I10: 1 | J10: 0.24
A11: 10 | B11: 40544 | C11: 1 | D11: 0 | E11: 1 | F11: 9 | G11: FALSE | H11: 6 | I11: 1 | J11: 0.32
A12: 11 | B12: 40544 | C12: 1 | D12: 0 | E12: 1 | F12: 10 | G12: FALSE | H12: 6 | I12: 1 | J12: 0.38
A13: 12 | B13: 40544 | C13: 1 | D13: 0 | E13: 1 | F13: 11 | G13: FALSE | H13: 6 | I13: 1 | J13: 0.36
... A611: 610 | B611: 40571 | C611: 1 | D611: 0 | E611: 1 | F611: 15 | G611: FALSE | H611: 5 | I611: 2 | J611: 0.2

Sheet DATA SHEET 2
A1: instant | B1: atemp | C1: hum | D1: windspeed | E1: casual | F1: registered | G1: cnt
A2: 1 | B2: 0.2879 | C2: 0.81 | D2: 0 | E2: 3 | F2: 13 | G2: 16
A3: 2 | B3: 0.2727 | C3: 0.8 | D3: 0 | E3: 8 | F3: 32 | G3: 40
A4: 3 | B4: 0.2727 | C4: 0.8 | D4: 0 | E4: 5 | F4: 27 | G4: 32
A5: 4 | B5: 0.2879 | C5: 0.75 | D5: 0 | E5: 3 | F5: 10 | G5: 13
A6: 5 | B6: 0.2879 | C6: 0.75 | D6: 0 | E6: 0 | F6: 1 | G6: 1
A7: 6 | B7: 0.2576 | C7: 0.75 | D7: 0.0896 | E7: 0 | F7: 1 | G7: 1
A8: 7 | B8: 0.2727 | C8: 0.8 | D8: 0 | E8: 2 | F8: 0 | G8: 2
A9: 8 | B9: 0.2576 | C9: 0.86 | D9: 0 | E9: 1 | F9: 2 | G9: 3
A10: 9 | C10: 0.75 | D10: 0 | E10: 1 | F10: 7 | G10: 8
A11: 10 | B11: 0.3485 | C11: 0.76 | D11: 0 | E11: 8 | F11: 6 | G11: 14
A12: 11 | B12: 0.3939 | C12: 0.76 | D12: 0.2537 | E12: 12 | F12: 24 | G12: 36
A13: 12 | B13: 0.3333 | C13: 0.81 | D13: 0.2836 | E13: 26 | F13: 30 | G13: 56
A14: 13 | B14: 0.4242 | C14: 0.77 | D14: 0.2836 | E14: 29 | F14: 55 | G14: 84
A15: 14 | B15: 0.4545 | C15: 0.72 | D15: 0.2985 | E15: 47 | F15: 47 | G15: 94
A16: 15 | B16: 0.4545 | C16: 0.72 | D16: 0.2836 | E16: 35 | F16: 71 | G16: 106
A17: 16 | B17: 0.4394 | C17: 0.77 | D17: 0.2985 | E17: 40 | F17: 70 | G17: 110
A18: 17 | B18: 0.4242 | C18: 0.82 | D18: 0.2985 | E18: 41 | F18: 52 | G18: 93
A19: 18 | C19: 0.82 | D19: 0.2836 | E19: 15 | F19: 52 | G19: 67
A20: 19 | B20: 0.4242 | C20: 0.88 | D20: 0.2537 | E20: 9 | F20: 26 | G20: 35
A21: 20 | B21: 0.4242 | C21: 0.88 | D21: 0.2537 | E21: 6 | F21: 31 | G21: 37
A22: 21 | B22: 0.4091 | C22: 0.87 | D22: 0.2537 | E22: 11 | F22: 25 | G22: 36
A23: 22 | B23: 0.4091 | C23: 0.87 | D23: 0.194 | E23: 3 | F23: 31 | G23: 34
A24: 23 | B24: 0.4091 | C24: 0.94 | D24: 0.2239 | E24: 11 | F24: 17 | G24: 28
A25: 24 | C25: 0.88 | D25: 0.2985 | E25: 15 | F25: 24 | G25: 39
A26: 25 | B26: 0.4545 | C26: 0.88 | D26: 0.2985 | E26: 4 | F26: 13 | G26: 17
A27: 26 | B27: 0.4394 | C27: 0.94 | D27: 0.2537 | E27: 1 | F27: 16 | G27: 17
A28: 27 | B28: 0.4242 | C28: 1 | D28: 0.2836 | E28: 1 | F28: 8 | G28: 9
A29: 28 | B29: 0.4545 | C29: 0.94 | D29: 0.194 | E29: 2 | F29: 4 | G29: 6
A30: 29 | C30: 0.94 | D30: 0.194 | E30: 2 | F30: 1 | G30: 3
A31: 30 | B31: 0.4242 | C31: 0.77 | D31: 0.2985 | E31: 0 | F31: 2 | G31: 2
A32: 31 | B32: 0.4091 | C32: 0.76 | D32: 0.194 | E32: 0 | F32: 1 | G32: 1
A33: 32 | B33: 0.4091 | C33: 0.71 | D33: 0.2239 | E33: 0 | F33: 8 | G33: 8
A34: 33 | C34: 0.76 | D34: 0.2239 | E34: 1 | F34: 19 | G34: 20
A35: 34 | B35: 0.3485 | C35: 0.81 | D35: 0.2239 | E35: 7 | F35: 46 | G35: 53
A36: 35 | B36: 0.3333 | C36: 0.71 | D36: 0.2537 | E36: 16 | F36: 54 | G36: 70
A37: 36 | B37: 0.3333 | C37: 0.66 | D37: 0.2985 | E37: 20 | F37: 73 | G37: 93
A38: 37 | B38: 0.3485 | C38: 0.66 | D38: 0.1343 | E38: 11 | F38: 64 | G38: 75
A39: 38 | C39: 0.76 | D39: 0.194 | E39: 4 | F39: 55 | G39: 59
A40: 39 | B40: 0.3333 | C40: 0.81 | D40: 0.1642 | E40: 19 | F40: 55 | G40: 74
...

Sheet Merge2
A1: instant | B1: dteday | C1: season | D1: yr | E1: mnth | F1: hr | G1: holiday | H1: weekday | I1: weathersit | J1: temp | K1: atemp | L1: hum | M1: windspeed | N1: casual | O1: registered | P1: cnt
A2: 1 | B2: 40544 | C2: 1 | D2: 0 | E2: 1 | F2: 0 | G2: FALSE | H2: 6 | I2: 1 | J2: 0.24 | K2: 0.2879 | L2: 0.81 | M2: 0 | N2: 3 | O2: 13 | P2: 16
A3: 2 | B3: 40544 | C3: 1 | D3: 0 | E3: 1 | F3: 1 | G3: FALSE | H3: 6 | I3: 1 | J3: 0.22 | K3: 0.2727 | L3: 0.8 | M3: 0 | N3: 8 | O3: 32 | P3: 40
A4: 3 | B4: 40544 | C4: 1 | D4: 0 | E4: 1 | F4: 2 | G4: FALSE | H4: 6 | I4: 1 | J4: 0.22 | K4: 0.2727 | L4: 0.8 | M4: 0 | N4: 5 | O4: 27 | P4: 32
A5: 4 | B5: 40544 | C5: 1 | D5: 0 | E5: 1 | F5: 3 | G5: FALSE | H5: 6 | I5: 1 | J5: 0.24 | K5: 0.2879 | L5: 0.75 | M5: 0 | N5: 3 | O5: 10 | P5: 13
A6: 5 | B6: 40544 | C6: 1 | D6: 0 | E6: 1 | F6: 4 | G6: FALSE | H6: 6 | I6: 1 | J6: 0.24 | K6: 0.2879 | L6: 0.75 | M6: 0 | N6: 0 | O6: 1 | P6: 1
A7: 6 | B7: 40544 | C7: 1 | D7: 0 | E7: 1 | F7: 5 | G7: FALSE | H7: 6 | I7: 2 | J7: 0.24 | K7: 0.2576 | L7: 0.75 | M7: 0.0896 | N7: 0 | O7: 1 | P7: 1
A8: 7 | B8: 40544 | C8: 1 | D8: 0 | E8: 1 | F8: 6 | G8: FALSE | H8: 6 | I8: 1 | J8: 0.22 | K8: 0.2727 | L8: 0.8 | M8: 0 | N8: 2 | O8: 0 | P8: 2
A9: 8 | B9: 40544 | C9: 1 | D9: 0 | E9: 1 | F9: 7 | G9: FALSE | H9: 6 | I9: 1 | J9: 0.2 | K9: 0.2576 | L9: 0.86 | M9: 0 | N9: 1 | O9: 2 | P9: 3
A10: 9 | B10: 40544 | C10: 1 | D10: 0 | E10: 1 | F10: 8 | G10: FALSE | H10: 6 | I10: 1 | J10: 0.24 | L10: 0.75 | M10: 0 | N10: 1 | O10: 7 | P10: 8
A11: 10 | B11: 40544 | C11: 1 | D11: 0 | E11: 1 | F11: 9 | G11: FALSE | H11: 6 | I11: 1 | J11: 0.32 | K11: 0.3485 | L11: 0.76 | M11: 0 | N11: 8 | O11: 6 | P11: 14
A12: 11 | B12: 40544 | C12: 1 | D12: 0 | E12: 1 | F12: 10 | G12: FALSE | H12: 6 | I12: 1 | J12: 0.38 | K12: 0.3939 | L12: 0.76 | M12: 0.2537 | N12: 12 | O12: 24 | P12: 36
A13: 12 | B13: 40544 | C13: 1 | D13: 0 | E13: 1 | F13: 11 | G13: FALSE | H13: 6 | I13: 1 | J13: 0.36 | K13: 0.3333 | L13: 0.81 | M13: 0.2836 | N13: 26 | O13: 30 | P13: 56
A14: 13 | B14: 40544 | C14: 1 | D14: 0 | E14: 1 | F14: 12 | G14: FALSE | H14: 6 | I14: 1 | J14: 0.42 | K14: 0.4242 | L14: 0.77 | M14: 0.2836 | N14: 29 | O14: 55 | P14: 84
A15: 14 | B15: 40544 | C15: 1 | D15: 0 | E15: 1 | F15: 13 | G15: FALSE | H15: 6 | I15: 2 | J15: 0.46 | K15: 0.4545 | L15: 0.72 | M15: 0.2985 | N15: 47 | O15: 47 | P15: 94
A16: 15 | B16: 40544 | C16: 1 | D16: 0 | E16: 1 | F16: 14 | G16: FALSE | H16: 6 | I16: 2 | J16: 0.46 | K16: 0.4545 | L16: 0.72 | M16: 0.2836 | N16: 35 | O16: 71 | P16: 106
A17: 16 | B17: 40544 | C17: 1 | D17: 0 | E17: 1 | F17: 15 | G17: FALSE | H17: 6 | I17: 2 | J17: 0.44 | K17: 0.4394 | L17: 0.77 | M17: 0.2985 | N17: 40 | O17: 70 | P17: 110
A18: 17 | B18: 40544 | C18: 1 | D18: 0 | E18: 1 | F18: 16 | G18: FALSE | H18: 6 | I18: 2 | J18: 0.42 | K18: 0.4242 | L18: 0.82 | M18: 0.2985 | N18: 41 | O18: 52 | P18: 93
A19: 18 | B19: 40544 | C19: 1 | D19: 0 | E19: 1 | F19: 17 | G19: FALSE | H19: 6 | I19: 2 | J19: 0.44 | L19: 0.82 | M19: 0.2836 | N19: 15 | O19: 52 | P19: 67
A20: 19 | B20: 40544 | C20: 1 | D20: 0 | E20: 1 | F20: 18 | G20: FALSE | H20: 6 | I20: 3 | J20: 0.42 | K20: 0.4242 | L20: 0.88 | M20: 0.2537 | N20: 9 | O20: 26 | P20: 35
A21: 20 | B21: 40544 | C21: 1 | D21: 0 | E21: 1 | F21: 19 | G21: FALSE | H21: 6 | I21: 3 | J21: 0.42 | K21: 0.4242 | L21: 0.88 | M21: 0.2537 | N21: 6 | O21: 31 | P21: 37
A22: 21 | B22: 40544 | C22: 1 | D22: 0 | E22: 1 | F22: 20 | G22: FALSE | H22: 6 | I22: 2 | J22: 0.4 | K22: 0.4091 | L22: 0.87 | M22: 0.2537 | N22: 11 | O22: 25 | P22: 36
A23: 22 | B23: 40544 | C23: 1 | D23: 0 | E23: 1 | F23: 21 | G23: FALSE | H23: 6 | I23: 2 | J23: 0.4 | K23: 0.4091 | L23: 0.87 | M23: 0.194 | N23: 3 | O23: 31 | P23: 34
A24: 23 | B24: 40544 | C24: 1 | D24: 0 | E24: 1 | F24: 22 | G24: FALSE | H24: 6 | I24: 2 | J24: 0.4 | K24: 0.4091 | L24: 0.94 | M24: 0.2239 | N24: 11 | O24: 17 | P24: 28
A25: 24 | B25: 40544 | C25: 1 | D25: 0 | E25: 1 | F25: 23 | G25: FALSE | H25: 6 | I25: 2 | J25: 0.46 | L25: 0.88 | M25: 0.2985 | N25: 15 | O25: 24 | P25: 39
A26: 25 | B26: 40545 | C26: 1 | D26: 0 | E26: 1 | F26: 0 | G26: FALSE | H26: 0 | I26: 2 | J26: 0.46 | K26: 0.4545 | L26: 0.88 | M26: 0.2985 | N26: 4 | O26: 13 | P26: 17
A27: 26 | B27: 40545 | C27: 1 | D27: 0 | E27: 1 | F27: 1 | G27: FALSE | H27: 0 | I27: 2 | J27: 0.44 | K27: 0.4394 | L27: 0.94 | M27: 0.2537 | N27: 1 | O27: 16 | P27: 17
A28: 27 | B28: 40545 | C28: 1 | D28: 0 | E28: 1 | F28: 2 | G28: FALSE | H28: 0 | I28: 2 | J28: 0.42 | K28: 0.4242 | L28: 1 | M28: 0.2836 | N28: 1 | O28: 8 | P28: 9
A29: 28 | B29: 40545 | C29: 1 | D29: 0 | E29: 1 | F29: 3 | G29: FALSE | H29: 0 | I29: 2 | J29: 0.46 | K29: 0.4545 | L29: 0.94 | M29: 0.194 | N29: 2 | O29: 4 | P29: 6
A30: 29 | B30: 40545 | C30: 1 | D30: 0 | E30: 1 | F30: 4 | G30: FALSE | H30: 0 | I30: 2 | J30: 0.46 | L30: 0.94 | M30: 0.194 | N30: 2 | O30: 1 | P30: 3
A31: 30 | B31: 40545 | C31: 1 | D31: 0 | E31: 1 | F31: 6 | G31: FALSE | H31: 0 | I31: 3 | J31: 0.42 | K31: 0.4242 | L31: 0.77 | M31: 0.2985 | N31: 0 | O31: 2 | P31: 2
A32: 31 | B32: 40545 | C32: 1 | D32: 0 | E32: 1 | F32: 7 | G32: FALSE | H32: 0 | I32: 2 | J32: 0.4 | K32: 0.4091 | L32: 0.76 | M32: 0.194 | N32: 0 | O32: 1 | P32: 1
A33: 32 | B33: 40545 | C33: 1 | D33: 0 | E33: 1 | F33: 8 | G33: FALSE | H33: 0 | I33: 3 | J33: 0.4 | K33: 0.4091 | L33: 0.71 | M33: 0.2239 | N33: 0 | O33: 8 | P33: 8
A34: 33 | B34: 40545 | C34: 1 | D34: 0 | E34: 1 | F34: 9 | G34: FALSE | H34: 0 | I34: 2 | J34: 0.38 | L34: 0.76 | M34: 0.2239 | N34: 1 | O34: 19 | P34: 20
A35: 34 | B35: 40545 | C35: 1 | D35: 0 | E35: 1 | F35: 10 | G35: FALSE | H35: 0 | I35: 2 | J35: 0.36 | K35: 0.3485 | L35: 0.81 | M35: 0.2239 | N35: 7 | O35: 46 | P35: 53
A36: 35 | B36: 40545 | C36: 1 | D36: 0 | E36: 1 | F36: 11 | G36: FALSE | H36: 0 | I36: 2 | J36: 0.36 | K36: 0.3333 | L36: 0.71 | M36: 0.2537 | N36: 16 | O36: 54 | P36: 70
A37: 36 | B37: 40545 | C37: 1 | D37: 0 | E37: 1 | F37: 12 | G37: FALSE | H37: 0 | I37: 2 | J37: 0.36 | K37: 0.3333 | L37: 0.66 | M37: 0.2985 | N37: 20 | O37: 73 | P37: 93
A38: 37 | B38: 40545 | C38: 1 | D38: 0 | E38: 1 | F38: 13 | G38: FALSE | H38: 0 | I38: 2 | J38: 0.36 | K38: 0.3485 | L38: 0.66 | M38: 0.1343 | N38: 11 | O38: 64 | P38: 75
A39: 38 | B39: 40545 | C39: 1 | D39: 0 | E39: 1 | F39: 14 | G39: FALSE | H39: 0 | I39: 3 | J39: 0.36 | L39: 0.76 | M39: 0.194 | N39: 4 | O39: 55 | P39: 59
A40: 39 | B40: 40545 | C40: 1 | D40: 0 | E40: 1 | F40: 15 | G40: FALSE | H40: 0 | I40: 3 | J40: 0.34 | K40: 0.3333 | L40: 0.81 | M40: 0.1642 | N40: 19 | O40: 55 | P40: 74
...

Sheet Merge1+2
A1: instant | B1: dteday | C1: season | D1: yr | E1: mnth | F1: hr | G1: holiday | H1: weekday | I1: weathersit | J1: temp | K1: atemp | L1: hum | M1: windspeed | N1: casual | O1: registered | P1: cnt
A2: 1 | B2: 40544 | C2: 1 | D2: 0 | E2: 1 | F2: 0 | G2: FALSE | H2: 6 | I2: 1 | J2: 0.24 | K2: 0.2879 | L2: 0.81 | M2: 0 | N2: 3 | O2: 13 | P2: 16
A3: 2 | B3: 40544 | C3: 1 | D3: 0 | E3: 1 | F3: 1 | G3: FALSE | H3: 6 | I3: 1 | J3: 0.22 | K3: 0.2727 | L3: 0.8 | M3: 0 | N3: 8 | O3: 32 | P3: 40
A4: 3 | B4: 40544 | C4: 1 | D4: 0 | E4: 1 | F4: 2 | G4: FALSE | H4: 6 | I4: 1 | J4: 0.22 | K4: 0.2727 | L4: 0.8 | M4: 0 | N4: 5 | O4: 27 | P4: 32
A5: 4 | B5: 40544 | C5: 1 | D5: 0 | E5: 1 | F5: 3 | G5: FALSE | H5: 6 | I5: 1 | J5: 0.24 | K5: 0.2879 | L5: 0.75 | M5: 0 | N5: 3 | O5: 10 | P5: 13
A6: 5 | B6: 40544 | C6: 1 | D6: 0 | E6: 1 | F6: 4 | G6: FALSE | H6: 6 | I6: 1 | J6: 0.24 | K6: 0.2879 | L6: 0.75 | M6: 0 | N6: 0 | O6: 1 | P6: 1
A7: 6 | B7: 40544 | C7: 1 | D7: 0 | E7: 1 | F7: 5 | G7: FALSE | H7: 6 | I7: 2 | J7: 0.24 | K7: 0.2576 | L7: 0.75 | M7: 0.0896 | N7: 0 | O7: 1 | P7: 1
A8: 7 | B8: 40544 | C8: 1 | D8: 0 | E8: 1 | F8: 6 | G8: FALSE | H8: 6 | I8: 1 | J8: 0.22 | K8: 0.2727 | L8: 0.8 | M8: 0 | N8: 2 | O8: 0 | P8: 2
A9: 8 | B9: 40544 | C9: 1 | D9: 0 | E9: 1 | F9: 7 | G9: FALSE | H9: 6 | I9: 1 | J9: 0.2 | K9: 0.2576 | L9: 0.86 | M9: 0 | N9: 1 | O9: 2 | P9: 3
A10: 9 | B10: 40544 | C10: 1 | D10: 0 | E10: 1 | F10: 8 | G10: FALSE | H10: 6 | I10: 1 | J10: 0.24 | L10: 0.75 | M10: 0 | N10: 1 | O10: 7 | P10: 8
A11: 10 | B11: 40544 | C11: 1 | D11: 0 | E11: 1 | F11: 9 | G11: FALSE | H11: 6 | I11: 1 | J11: 0.32 | K11: 0.3485 | L11: 0.76 | M11: 0 | N11: 8 | O11: 6 | P11: 14
A12: 11 | B12: 40544 | C12: 1 | D12: 0 | E12: 1 | F12: 10 | G12: FALSE | H12: 6 | I12: 1 | J12: 0.38 | K12: 0.3939 | L12: 0.76 | M12: 0.2537 | N12: 12 | O12: 24 | P12: 36
A13: 12 | B13: 40544 | C13: 1 | D13: 0 | E13: 1 | F13: 11 | G13: FALSE | H13: 6 | I13: 1 | J13: 0.36 | K13: 0.3333 | L13: 0.81 | M13: 0.2836 | N13: 26 | O13: 30 | P13: 56
A14: 13 | B14: 40544 | C14: 1 | D14: 0 | E14: 1 | F14: 12 | G14: FALSE | H14: 6 | I14: 1 | J14: 0.42 | K14: 0.4242 | L14: 0.77 | M14: 0.2836 | N14: 29 | O14: 55 | P14: 84
A15: 14 | B15: 40544 | C15: 1 | D15: 0 | E15: 1 | F15: 13 | G15: FALSE | H15: 6 | I15: 2 | J15: 0.46 | K15: 0.4545 | L15: 0.72 | M15: 0.2985 | N15: 47 | O15: 47 | P15: 94
A16: 15 | B16: 40544 | C16: 1 | D16: 0 | E16: 1 | F16: 14 | G16: FALSE | H16: 6 | I16: 2 | J16: 0.46 | K16: 0.4545 | L16: 0.72 | M16: 0.2836 | N16: 35 | O16: 71 | P16: 106
A17: 16 | B17: 40544 | C17: 1 | D17: 0 | E17: 1 | F17: 15 | G17: FALSE | H17: 6 | I17: 2 | J17: 0.44 | K17: 0.4394 | L17: 0.77 | M17: 0.2985 | N17: 40 | O17: 70 | P17: 110
A18: 17 | B18: 40544 | C18: 1 | D18: 0 | E18: 1 | F18: 16 | G18: FALSE | H18: 6 | I18: 2 | J18: 0.42 | K18: 0.4242 | L18: 0.82 | M18: 0.2985 | N18: 41 | O18: 52 | P18: 93
A19: 18 | B19: 40544 | C19: 1 | D19: 0 | E19: 1 | F19: 17 | G19: FALSE | H19: 6 | I19: 2 | J19: 0.44 | L19: 0.82 | M19: 0.2836 | N19: 15 | O19: 52 | P19: 67
A20: 19 | B20: 40544 | C20: 1 | D20: 0 | E20: 1 | F20: 18 | G20: FALSE | H20: 6 | I20: 3 | J20: 0.42 | K20: 0.4242 | L20: 0.88 | M20: 0.2537 | N20: 9 | O20: 26 | P20: 35
A21: 20 | B21: 40544 | C21: 1 | D21: 0 | E21: 1 | F21: 19 | G21: FALSE | H21: 6 | I21: 3 | J21: 0.42 | K21: 0.4242 | L21: 0.88 | M21: 0.2537 | N21: 6 | O21: 31 | P21: 37
A22: 21 | B22: 40544 | C22: 1 | D22: 0 | E22: 1 | F22: 20 | G22: FALSE | H22: 6 | I22: 2 | J22: 0.4 | K22: 0.4091 | L22: 0.87 | M22: 0.2537 | N22: 11 | O22: 25 | P22: 36
A23: 22 | B23: 40544 | C23: 1 | D23: 0 | E23: 1 | F23: 21 | G23: FALSE | H23: 6 | I23: 2 | J23: 0.4 | K23: 0.4091 | L23: 0.87 | M23: 0.194 | N23: 3 | O23: 31 | P23: 34
A24: 23 | B24: 40544 | C24: 1 | D24: 0 | E24: 1 | F24: 22 | G24: FALSE | H24: 6 | I24: 2 | J24: 0.4 | K24: 0.4091 | L24: 0.94 | M24: 0.2239 | N24: 11 | O24: 17 | P24: 28
A25: 24 | B25: 40544 | C25: 1 | D25: 0 | E25: 1 | F25: 23 | G25: FALSE | H25: 6 | I25: 2 | J25: 0.46 | L25: 0.88 | M25: 0.2985 | N25: 15 | O25: 24 | P25: 39
A26: 25 | B26: 40545 | C26: 1 | D26: 0 | E26: 1 | F26: 0 | G26: FALSE | H26: 0 | I26: 2 | J26: 0.46 | K26: 0.4545 | L26: 0.88 | M26: 0.2985 | N26: 4 | O26: 13 | P26: 17
A27: 26 | B27: 40545 | C27: 1 | D27: 0 | E27: 1 | F27: 1 | G27: FALSE | H27: 0 | I27: 2 | J27: 0.44 | K27: 0.4394 | L27: 0.94 | M27: 0.2537 | N27: 1 | O27: 16 | P27: 17
A28: 27 | B28: 40545 | C28: 1 | D28: 0 | E28: 1 | F28: 2 | G28: FALSE | H28: 0 | I28: 2 | J28: 0.42 | K28: 0.4242 | L28: 1 | M28: 0.2836 | N28: 1 | O28: 8 | P28: 9
A29: 28 | B29: 40545 | C29: 1 | D29: 0 | E29: 1 | F29: 3 | G29: FALSE | H29: 0 | I29: 2 | J29: 0.46 | K29: 0.4545 | L29: 0.94 | M29: 0.194 | N29: 2 | O29: 4 | P29: 6
A30: 29 | B30: 40545 | C30: 1 | D30: 0 | E30: 1 | F30: 4 | G30: FALSE | H30: 0 | I30: 2 | J30: 0.46 | L30: 0.94 | M30: 0.194 | N30: 2 | O30: 1 | P30: 3
A31: 30 | B31: 40545 | C31: 1 | D31: 0 | E31: 1 | F31: 6 | G31: FALSE | H31: 0 | I31: 3 | J31: 0.42 | K31: 0.4242 | L31: 0.77 | M31: 0.2985 | N31: 0 | O31: 2 | P31: 2
A32: 31 | B32: 40545 | C32: 1 | D32: 0 | E32: 1 | F32: 7 | G32: FALSE | H32: 0 | I32: 2 | J32: 0.4 | K32: 0.4091 | L32: 0.76 | M32: 0.194 | N32: 0 | O32: 1 | P32: 1
A33: 32 | B33: 40545 | C33: 1 | D33: 0 | E33: 1 | F33: 8 | G33: FALSE | H33: 0 | I33: 3 | J33: 0.4 | K33: 0.4091 | L33: 0.71 | M33: 0.2239 | N33: 0 | O33: 8 | P33: 8
A34: 33 | B34: 40545 | C34: 1 | D34: 0 | E34: 1 | F34: 9 | G34: FALSE | H34: 0 | I34: 2 | J34: 0.38 | L34: 0.76 | M34: 0.2239 | N34: 1 | O34: 19 | P34: 20
A35: 34 | B35: 40545 | C35: 1 | D35: 0 | E35: 1 | F35: 10 | G35: FALSE | H35: 0 | I35: 2 | J35: 0.36 | K35: 0.3485 | L35: 0.81 | M35: 0.2239 | N35: 7 | O35: 46 | P35: 53
A36: 35 | B36: 40545 | C36: 1 | D36: 0 | E36: 1 | F36: 11 | G36: FALSE | H36: 0 | I36: 2 | J36: 0.36 | K36: 0.3333 | L36: 0.71 | M36: 0.2537 | N36: 16 | O36: 54 | P36: 70
A37: 36 | B37: 40545 | C37: 1 | D37: 0 | E37: 1 | F37: 12 | G37: FALSE | H37: 0 | I37: 2 | J37: 0.36 | K37: 0.3333 | L37: 0.66 | M37: 0.2985 | N37: 20 | O37: 73 | P37: 93
A38: 37 | B38: 40545 | C38: 1 | D38: 0 | E38: 1 | F38: 13 | G38: FALSE | H38: 0 | I38: 2 | J38: 0.36 | K38: 0.3485 | L38: 0.66 | M38: 0.1343 | N38: 11 | O38: 64 | P38: 75
A39: 38 | B39: 40545 | C39: 1 | D39: 0 | E39: 1 | F39: 14 | G39: FALSE | H39: 0 | I39: 3 | J39: 0.36 | L39: 0.76 | M39: 0.194 | N39: 4 | O39: 55 | P39: 59
A40: 39 | B40: 40545 | C40: 1 | D40: 0 | E40: 1 | F40: 15 | G40: FALSE | H40: 0 | I40: 3 | J40: 0.34 | K40: 0.3333 | L40: 0.81 | M40: 0.1642 | N40: 19 | O40: 55 | P40: 74
...

Sheet Sheet5
A1: mnth2 | B1: weekday2 | C1: holiday2 | D1: weathersit | E1: temp | F1: atemp
A2: 1 | B2: 6 | C2: FALSE | D2: 1 | E2: 0.24 | F2: 0.2879
A3: 1 | B3: 6 | C3: FALSE | D3: 1 | E3: 0.22 | F3: 0.2727
A4: 1 | B4: 6 | C4: FALSE | D4: 1 | E4: 0.22 | F4: 0.2727
A5: 1 | B5: 6 | C5: FALSE | D5: 1 | E5: 0.24 | F5: 0.2879
A6: 1 | B6: 6 | C6: FALSE | D6: 1 | E6: 0.24 | F6: 0.2879
A7: 1 | B7: 6 | C7: FALSE | D7: 2 | E7: 0.24 | F7: 0.2576
A8: 1 | B8: 6 | C8: FALSE | D8: 1 | E8: 0.22 | F8: 0.2727
A9: 1 | B9: 6 | C9: FALSE | D9: 1 | E9: 0.2 | F9: 0.2576
A10: 1 | B10: 6 | C10: FALSE | D10: 1 | E10: 0.24
A11: 1 | B11: 6 | C11: FALSE | D11: 1 | E11: 0.32 | F11: 0.3485
A12: 1 | B12: 6 | C12: FALSE | D12: 1 | E12: 0.38 | F12: 0.3939
A13: 1 | B13: 6 | C13: FALSE | D13: 1 | E13: 0.36 | F13: 0.3333
A14: 1 | B14: 6 | C14: FALSE | D14: 1 | E14: 0.42 | F14: 0.4242
A15: 1 | B15: 6 | C15: FALSE | D15: 2 | E15: 0.46 | F15: 0.4545
A16: 1 | B16: 6 | C16: FALSE | D16: 2 | E16: 0.46 | F16: 0.4545
A17: 1 | B17: 6 | C17: FALSE | D17: 2 | E17: 0.44 | F17: 0.4394
A18: 1 | B18: 6 | C18: FALSE | D18: 2 | E18: 0.42 | F18: 0.4242
A19: 1 | B19: 6 | C19: FALSE | D19: 2 | E19: 0.44
A20: 1 | B20: 6 | C20: FALSE | D20: 3 | E20: 0.42 | F20: 0.4242
A21: 1 | B21: 6 | C21: FALSE | D21: 3 | E21: 0.42 | F21: 0.4242
A22: 1 | B22: 6 | C22: FALSE | D22: 2 | E22: 0.4 | F22: 0.4091
A23: 1 | B23: 6 | C23: FALSE | D23: 2 | E23: 0.4 | F23: 0.4091
A24: 1 | B24: 6 | C24: FALSE | D24: 2 | E24: 0.4 | F24: 0.4091
A25: 1 | B25: 6 | C25: FALSE | D25: 2 | E25: 0.46
A26: 1 | B26: 0 | C26: FALSE | D26: 2 | E26: 0.46 | F26: 0.4545
A27: 1 | B27: 0 | C27: FALSE | D27: 2 | E27: 0.44 | F27: 0.4394
A28: 1 | B28: 0 | C28: FALSE | D28: 2 | E28: 0.42 | F28: 0.4242
A29: 1 | B29: 0 | C29: FALSE | D29: 2 | E29: 0.46 | F29: 0.4545
A30: 1 | B30: 0 | C30: FALSE | D30: 2 | E30: 0.46
A31: 1 | B31: 0 | C31: FALSE | D31: 3 | E31: 0.42 | F31: 0.4242
A32: 1 | B32: 0 | C32: FALSE | D32: 2 | E32: 0.4 | F32: 0.4091
A33: 1 | B33: 0 | C33: FALSE | D33: 3 | E33: 0.4 | F33: 0.4091
A34: 1 | B34: 0 | C34: FALSE | D34: 2 | E34: 0.38
A35: 1 | B35: 0 | C35: FALSE | D35: 2 | E35: 0.36 | F35: 0.3485
A36: 1 | B36: 0 | C36: FALSE | D36: 2 | E36: 0.36 | F36: 0.3333
A37: 1 | B37: 0 | C37: FALSE | D37: 2 | E37: 0.36 | F37: 0.3333
A38: 1 | B38: 0 | C38: FALSE | D38: 2 | E38: 0.36 | F38: 0.3485
A39: 1 | B39: 0 | C39: FALSE | D39: 3 | E39: 0.36
A40: 1 | B40: 0 | C40: FALSE | D40: 3 | E40: 0.34 | F40: 0.3333
...

Sheet Detail1
A1: Details for Average of cnt - weekday: Sunday
A3: instant | B3: dteday | C3: season | D3: mnth | E3: hr | F3: holiday | G3: weekday | H3: Column1 | I3: TEMPERATURE | J3: temp | K3: atemp | L3: hum | M3: windspeed | N3: casual | O3: registered | P3: cnt
A4: 25 | B4: 40545 | C4: winter | D4: JANUARY | E4: 0 | F4: NO | G4: Sunday | H4: Afternoon | I4: 18.86 | J4: 0.46 | K4: 0.4545 | L4: 0.88 | M4: 0.2985 | N4: 4 | O4: 13 | P4: 17
A5: 26 | B5: 40545 | C5: winter | D5: JANUARY | E5: 1 | F5: NO | G5: Sunday | H5: Afternoon | I5: 18.04 | J5: 0.44 | K5: 0.4394 | L5: 0.94 | M5: 0.2537 | N5: 1 | O5: 16 | P5: 17
A6: 27 | B6: 40545 | C6: winter | D6: JANUARY | E6: 2 | F6: NO | G6: Sunday | H6: Afternoon | I6: 17.22 | J6: 0.42 | K6: 0.4242 | L6: 1 | M6: 0.2836 | N6: 1 | O6: 8 | P6: 9
A7: 28 | B7: 40545 | C7: winter | D7: JANUARY | E7: 3 | F7: NO | G7: Sunday | H7: Afternoon | I7: 18.86 | J7: 0.46 | K7: 0.4545 | L7: 0.94 | M7: 0.194 | N7: 2 | O7: 4 | P7: 6
A8: 29 | B8: 40545 | C8: winter | D8: JANUARY | E8: 4 | F8: NO | G8: Sunday | H8: Afternoon | I8: 18.86 | J8: 0.46 | L8: 0.94 | M8: 0.194 | N8: 2 | O8: 1 | P8: 3
A9: 30 | B9: 40545 | C9: winter | D9: JANUARY | E9: 6 | F9: NO | G9: Sunday | H9: Evening | I9: 17.22 | J9: 0.42 | K9: 0.4242 | L9: 0.77 | M9: 0.2985 | N9: 0 | O9: 2 | P9: 2
A10: 31 | B10: 40545 | C10: winter | D10: JANUARY | E10: 7 | F10: NO | G10: Sunday | H10: Afternoon | I10: 16.4 | J10: 0.4 | K10: 0.4091 | L10: 0.76 | M10: 0.194 | N10: 0 | O10: 1 | P10: 1
A11: 32 | B11: 40545 | C11: winter | D11: JANUARY | E11: 8 | F11: NO | G11: Sunday | H11: Evening | I11: 16.4 | J11: 0.4 | K11: 0.4091 | L11: 0.71 | M11: 0.2239 | N11: 0 | O11: 8 | P11: 8
A12: 33 | B12: 40545 | C12: winter | D12: JANUARY | E12: 9 | F12: NO | G12: Sunday | H12: Afternoon | I12: 15.58 | J12: 0.38 | L12: 0.76 | M12: 0.2239 | N12: 1 | O12: 19 | P12: 20
A13: 34 | B13: 40545 | C13: winter | D13: JANUARY | E13: 10 | F13: NO | G13: Sunday | H13: Afternoon | I13: 14.76 | J13: 0.36 | K13: 0.3485 | L13: 0.81 | M13: 0.2239 | N13: 7 | O13: 46 | P13: 53
A14: 35 | B14: 40545 | C14: winter | D14: JANUARY | E14: 11 | F14: NO | G14: Sunday | H14: Afternoon | I14: 14.76 | J14: 0.36 | K14: 0.3333 | L14: 0.71 | M14: 0.2537 | N14: 16 | O14: 54 | P14: 70
A15: 36 | B15: 40545 | C15: winter | D15: JANUARY | E15: 12 | F15: NO | G15: Sunday | H15: Afternoon | I15: 14.76 | J15: 0.36 | K15: 0.3333 | L15: 0.66 | M15: 0.2985 | N15: 20 | O15: 73 | P15: 93
A16: 37 | B16: 40545 | C16: winter | D16: JANUARY | E16: 13 | F16: NO | G16: Sunday | H16: Afternoon | I16: 14.76 | J16: 0.36 | K16: 0.3485 | L16: 0.66 | M16: 0.1343 | N16: 11 | O16: 64 | P16: 75
A17: 38 | B17: 40545 | C17: winter | D17: JANUARY | E17: 14 | F17: NO | G17: Sunday | H17: Evening | I17: 14.76 | J17: 0.36 | L17: 0.76 | M17: 0.194 | N17: 4 | O17: 55 | P17: 59
A18: 39 | B18: 40545 | C18: winter | D18: JANUARY | E18: 15 | F18: NO | G18: Sunday | H18: Evening | I18: 13.94 | J18: 0.34 | K18: 0.3333 | L18: 0.81 | M18: 0.1642 | N18: 19 | O18: 55 | P18: 74
A19: 40 | B19: 40545 | C19: winter | D19: JANUARY | E19: 16 | F19: NO | G19: Sunday | H19: Evening | I19: 13.94 | J19: 0.34 | K19: 0.3333 | L19: 0.71 | M19: 0.1642 | N19: 9 | O19: 67 | P19: 76
A20: 41 | B20: 40545 | C20: winter | D20: JANUARY | E20: 17 | F20: NO | G20: Sunday | H20: Morning | I20: 13.94 | J20: 0.34 | K20: 0.3333 | L20: 0.57 | M20: 0.194 | N20: 7 | O20: 58 | P20: 65
A21: 42 | B21: 40545 | C21: winter | D21: JANUARY | E21: 18 | F21: NO | G21: Sunday | H21: Afternoon | I21: 14.76 | J21: 0.36 | K21: 0.3333 | L21: 0.46 | M21: 0.3284 | N21: 10 | O21: 43 | P21: 53
A22: 43 | B22: 40545 | C22: winter | D22: JANUARY | E22: 19 | F22: NO | G22: Sunday | H22: Morning | I22: 13.12 | J22: 0.32 | K22: 0.2879 | L22: 0.42 | M22: 0.4478 | N22: 1 | O22: 29 | P22: 30
A23: 44 | B23: 40545 | C23: winter | D23: JANUARY | E23: 20 | F23: NO | G23: Sunday | H23: Morning | I23: 12.3 | J23: 0.3 | L23: 0.39 | M23: 0.3582 | N23: 5 | O23: 17 | P23: 22
A24: 45 | B24: 40545 | C24: winter | D24: JANUARY | E24: 21 | F24: NO | G24: Sunday | H24: Morning | I24: 10.66 | J24: 0.26 | K24: 0.2273 | L24: 0.44 | M24: 0.3284 | N24: 11 | O24: 20 | P24: 31
A25: 46 | B25: 40545 | C25: winter | D25: JANUARY | E25: 22 | F25: NO | G25: Sunday | H25: Morning | I25: 9.84 | J25: 0.24 | K25: 0.2121 | L25: 0.44 | M25: 0.2985 | N25: 0 | O25: 9 | P25: 9
A26: 47 | B26: 40545 | C26: winter | D26: JANUARY | E26: 23 | F26: NO | G26: Sunday | H26: Morning | I26: 9.02 | J26: 0.22 | K26: 0.2273 | L26: 0.47 | M26: 0.1642 | N26: 0 | O26: 8 | P26: 8
A27: 186 | B27: 40552 | C27: winter | D27: JANUARY | E27: 0 | F27: NO | G27: Sunday | H27: Morning | I27: 4.1 | J27: 0.1 | K27: 0.0758 | L27: 0.42 | M27: 0.3881 | N27: 1 | O27: 24 | P27: 25
A28: 187 | B28: 40552 | C28: winter | D28: JANUARY | E28: 1 | F28: NO | G28: Sunday | H28: Morning | I28: 4.1 | J28: 0.1 | K28: 0.0606 | L28: 0.42 | M28: 0.4627 | N28: 0 | O28: 12 | P28: 12
A29: 188 | B29: 40552 | C29: winter | D29: JANUARY | E29: 2 | F29: NO | G29: Sunday | H29: Morning | I29: 4.1 | J29: 0.1 | K29: 0.0606 | L29: 0.46 | M29: 0.4627 | N29: 0 | O29: 11 | P29: 11
A30: 189 | B30: 40552 | C30: winter | D30: JANUARY | E30: 3 | F30: NO | G30: Sunday | H30: Morning | I30: 4.1 | J30: 0.1 | K30: 0.0758 | L30: 0.46 | M30: 0.4179 | N30: 0 | O30: 4 | P30: 4
A31: 190 | B31: 40552 | C31: winter | D31: JANUARY | E31: 4 | F31: NO | G31: Sunday | H31: Morning | I31: 3.28 | J31: 0.08 | K31: 0.0909 | L31: 0.53 | M31: 0.194 | N31: 0 | O31: 1 | P31: 1
A32: 191 | B32: 40552 | C32: winter | D32: JANUARY | E32: 5 | F32: NO | G32: Sunday | H32: Morning | I32: 3.28 | J32: 0.08 | K32: 0.0909 | L32: 0.53 | M32: 0.194 | N32: 0 | O32: 1 | P32: 1
A33: 192 | B33: 40552 | C33: winter | D33: JANUARY | E33: 6 | F33: NO | G33: Sunday | H33: Morning | I33: 4.1 | J33: 0.1 | K33: 0.0909 | L33: 0.49 | M33: 0.2836 | N33: 0 | O33: 1 | P33: 1
A34: 193 | B34: 40552 | C34: winter | D34: JANUARY | E34: 7 | F34: NO | G34: Sunday | H34: Morning | I34: 3.28 | J34: 0.08 | K34: 0.0909 | L34: 0.53 | M34: 0.194 | N34: 1 | O34: 5 | P34: 6
A35: 194 | B35: 40552 | C35: winter | D35: JANUARY | E35: 8 | F35: NO | G35: Sunday | H35: Morning | I35: 4.1 | J35: 0.1 | K35: 0.0909 | L35: 0.49 | M35: 0.2836 | N35: 0 | O35: 10 | P35: 10
... A167: 992 | B167: 40587 | C167: winter | D167: FEBRUARY | E167: 23 | F167: NO | G167: Sunday | H167: Morning | I167: 16.4 | J167: 0.4 | K167: 0.4091 | L167: 0.35 | M167: 0.3582 | N167: 3 | O167: 27 | P167: 30

Sheet Sheet2
A3: Row Labels | B3: Sum of registered
A4: 01-Jan | B4: 654
A5: 02-Jan | B5: 670
A6: 03-Jan | B6: 1229
A7: 04-Jan | B7: 1454
A8: 05-Jan | B8: 1518
A9: 06-Jan | B9: 1518
A10: 07-Jan | B10: 1362
A11: 08-Jan | B11: 891
A12: 09-Jan | B12: 768
A13: 10-Jan | B13: 1280
A14: 11-Jan | B14: 1220
A15: 12-Jan | B15: 1137
... A49: Grand Total | B49: 53383

Sheet Sheet3

Sheet Sheet4
A3: Row Labels | B3: Average of hum | C3: Average of windspeed | D3: Sum of registered
A4: Sunday | B4: 0.54176829 | C4: 0.21769817 | D4: 6644
A5: Monday | B5: 0.54503356 | C5: 0.18191007 | D5: 7916
A6: Tuesday | B6: 0.67086614 | C6: 0.16559843 | D6: 7926
A7: Wednesday | B7: 0.6419084 | C7: 0.23801603 | D7: 7705
A8: Thursday | B8: 0.49408 | C8: 0.2111136 | D8: 8126
A9: Friday | B9: 0.56268116 | C9: 0.16980725 | D9: 8543
A10: Saturday | B10: 0.62481928 | C10: 0.18126807 | D10: 6523
A11: Grand Total | B11: 0.58248 | C11: 0.1949313 | D11: 53383
A15: Row Labels | B15: Average of hum | C15: Average of temp
A16: Jan
A17: 01-Jan | B17: 0.80583333 | C17: 0.34416667
A18: 02-Jan | B18: 0.69608696 | C18: 0.36347826
A19: 03-Jan | B19: 0.43727273 | C19: 0.19636364
A20: 04-Jan | B20: 0.59043478 | C20: 0.2
A21: 05-Jan | B21: 0.43695652 | C21: 0.22695652
A22: 06-Jan | B22: 0.51826087 | C22: 0.20434783
A23: 07-Jan | B23: 0.49869565 | C23: 0.19652174
A24: 08-Jan | B24: 0.53583333 | C24: 0.165 | E24: Row Labels
A25: 09-Jan | B25: 0.43416667 | C25: 0.13833333 | E25: Clear Sky
A26: 10-Jan | B26: 0.48291667 | C26: 0.15083333 | E26: Dark Cloud
A27: 11-Jan | B27: 0.68636364 | C27: 0.16909091 | E27: Heavy Rainfall
A28: 12-Jan | B28: 0.59954545 | C28: 0.17272727 | E28: Mist
A29: 13-Jan | B29: 0.47041667 | C29: 0.165 | E29: Grand Total
A30: 14-Jan | B30: 0.53782609 | C30: 0.16086957
A31: 15-Jan | B31: 0.49875 | C31: 0.23333333
A32: 16-Jan | B32: 0.48375 | C32: 0.23166667
A33: 17-Jan | B33: 0.5375 | C33: 0.17583333
A34: 18-Jan | B34: 0.86166667 | C34: 0.21666667
A35: 19-Jan | B35: 0.74173913 | C35: 0.29217391
A36: 20-Jan | B36: 0.53833333 | C36: 0.26166667
A37: 21-Jan | B37: 0.45708333 | C37: 0.1775
A38: 22-Jan | B38: 0.4 | C38: 0.059130435
A39: 23-Jan | B39: 0.43652174 | C39: 0.096521739
A40: 24-Jan | B40: 0.49173913 | C40: 0.097391304
A41: 25-Jan | B41: 0.61695652 | C41: 0.22347826
... A47: 31-Jan | B47: 0.60375 | C47: 0.18083333
A48: Feb
A49: 01-Feb | B49: 0.82956522 | C49: 0.19217391
A50: 02-Feb | B50: 0.77541667 | C50: 0.26
...

Sheet Sheet1
A3: Row Labels | B3: Sum of cnt
A4: NO | B4: 57304
A5: Sunday | B5: 8121
A6: Monday | B6: 7450
A7: Tuesday | B7: 8383
A8: Wednesday | B8: 8049
A9: Thursday | B9: 8458
A10: Friday | B10: 9095
A11: Saturday | B11: 7748
A12: YES | B12: 1000
A13: Monday | B13: 1000
A14: Grand Total | B14: 58304
B19: Row Labels | C19: Average of cnt
B20: Jan
B21: 01-Jan
B22: 40544 | C22: 41.041667
B23: Afternoon | C23: 60.8
B24: Evening | C24: 36
B25: Morning | C25: 25.416667
B26: 02-Jan
B27: 40545 | C27: 34.826087
B28: Afternoon | C28: 34.75
B29: Evening | C29: 43.8
B30: Morning | C30: 27.5
B31: Grand Total | C31: 38

Sheet final data
A1: instant | B1: dteday | C1: season | D1: mnth | E1: hr | F1: holiday | G1: weekday | H1: Weather | I1: TEMPERATURE | J1: hum | K1: windspeed | L1: casual | M1: registered | N1: cnt
A2: 1 | B2: 40544 | C2: winter | D2: {=_xlfn.SWITCH(Sheet5!A2,1,"JANUARY",2,"FEBRUARY")} -> JANUARY | E2: 0 | F2: {=_xlfn.SWITCH(Sheet5!C2,FALSE,"NO",TRUE,"YES")} -> NO | G2: {=_xlfn.SWITCH(Sheet5!B2,0,"Sunday",1,"Monday",2,"Tuesday",3,"Wednesday",4,"Thursday",5,"Friday",6,"Saturday")} -> Saturday | H2: {=_xlfn.SWITCH(Sheet5!D2, 1, "Clear Sky", 2, "Mist", 3, "Dark Cloud",4,"Heavy Rainfall")} -> Clear Sky | I2: =Sheet5!E2*41 -> 9.84 | J2: 0.81 | K2: 0 | L2: 3 | M2: 13 | N2: 16
A3: 2 | B3: 40544 | C3: winter | D3: {=_xlfn.SWITCH(Sheet5!A3,1,"JANUARY",2,"FEBRUARY")} -> JANUARY | E3: 1 | F3: {=_xlfn.SWITCH(Sheet5!C3,FALSE,"NO",TRUE,"YES")} -> NO | G3: {=_xlfn.SWITCH(Sheet5!B3,0,"Sunday",1,"Monday",2,"Tuesday",3,"Wednesday",4,"Thursday",5,"Friday",6,"Saturday")} -> Saturday | H3: {=_xlfn.SWITCH(Sheet5!D3, 1, "Clear Sky", 2, "Mist", 3, "Dark Cloud",4,"Heavy Rainfall")} -> Clear Sky | I3: =Sheet5!E3*41 -> 9.02 | J3: 0.8 | K3: 0 | L3: 8 | M3: 32 | N3: 40
A4: 3 | B4: 40544 | C4: winter | D4: {=_xlfn.SWITCH(Sheet5!A4,1,"JANUARY",2,"FEBRUARY")} -> JANUARY | E4: 2 | F4: {=_xlfn.SWITCH(Sheet5!C4,FALSE,"NO",TRUE,"YES")} -> NO | G4: {=_xlfn.SWITCH(Sheet5!B4,0,"Sunday",1,"Monday",2,"Tuesday",3,"Wednesday",4,"Thursday",5,"Friday",6,"Saturday")} -> Saturday | H4: {=_xlfn.SWITCH(Sheet5!D4, 1, "Clear Sky", 2, "Mist", 3, "Dark Cloud",4,"Heavy Rainfall")} -> Clear Sky | I4: =Sheet5!E4*41 -> 9.02 | J4: 0.8 | K4: 0 | L4: 5 | M4: 27 | N4: 32
A5: 4 | B5: 40544 | C5: winter | D5: {=_xlfn.SWITCH(Sheet5!A5,1,"JANUARY",2,"FEBRUARY")} -> JANUARY | E5: 3 | F5: {=_xlfn.SWITCH(Sheet5!C5,FALSE,"NO",TRUE,"YES")} -> NO | G5: {=_xlfn.SWITCH(Sheet5!B5,0,"Sunday",1,"Monday",2,"Tuesday",3,"Wednesday",4,"Thursday",5,"Friday",6,"Saturday")} -> Saturday | H5: {=_xlfn.SWITCH(Sheet5!D5, 1, "Clear Sky", 2, "Mist", 3, "Dark Cloud",4,"Heavy Rainfall")} -> Clear Sky | I5: =Sheet5!E5*41 -> 9.84 | J5: 0.75 | K5: 0 | L5: 3 | M5: 10 | N5: 13
A6: 5 | B6: 40544 | C6: winter | D6: {=_xlfn.SWITCH(Sheet5!A6,1,"JANUARY",2,"FEBRUARY")} -> JANUARY | E6: 4 | F6: {=_xlfn.SWITCH(Sheet5!C6,FALSE,"NO",TRUE,"YES")} -> NO | G6: {=_xlfn.SWITCH(Sheet5!B6,0,"Sunday",1,"Monday",2,"Tuesday",3,"Wednesday",4,"Thursday",5,"Friday",6,"Saturday")} -> Saturday | H6: {=_xlfn.SWITCH(Sheet5!D6, 1, "Clear Sky", 2, "Mist", 3, "Dark Cloud",4,"Heavy Rainfall")} -> Clear Sky | I6: =Sheet5!E6*41 -> 9.84 | J6: 0.75 | K6: 0 | L6: 0 | M6: 1 | N6: 1
A7: 6 | B7: 40544 | C7: winter | D7: {=_xlfn.SWITCH(Sheet5!A7,1,"JANUARY",2,"FEBRUARY")} -> JANUARY | E7: 5 | F7: {=_xlfn.SWITCH(Sheet5!C7,FALSE,"NO",TRUE,"YES")} -> NO | G7: {=_xlfn.SWITCH(Sheet5!B7,0,"Sunday",1,"Monday",2,"Tuesday",3,"Wednesday",4,"Thursday",5,"Friday",6,"Saturday")} -> Saturday | H7: {=_xlfn.SWITCH(Sheet5!D7, 1, "Clear Sky", 2, "Mist", 3, "Dark Cloud",4,"Heavy Rainfall")} -> Mist | I7: =Sheet5!E7*41 -> 9.84 | J7: 0.75 | K7: 0.0896 | L7: 0 | M7: 1 | N7: 1
A8: 7 | B8: 40544 | C8: winter | D8: {=_xlfn.SWITCH(Sheet5!A8,1,"JANUARY",2,"FEBRUARY")} -> JANUARY | E8: 6 | F8: {=_xlfn.SWITCH(Sheet5!C8,FALSE,"NO",TRUE,"YES")} -> NO | G8: {=_xlfn.SWITCH(Sheet5!B8,0,"Sunday",1,"Monday",2,"Tuesday",3,"Wednesday",4,"Thursday",5,"Friday",6,"Saturday")} -> Saturday | H8: {=_xlfn.SWITCH(Sheet5!D8, 1, "Clear Sky", 2, "Mist", 3, "Dark Cloud",4,"Heavy Rainfall")} -> Clear Sky | I8: =Sheet5!E8*41 -> 9.02 | J8: 0.8 | K8: 0 | L8: 2 | M8: 0 | N8: 2
A9: 8 | B9: 40544 | C9: winter | D9: {=_xlfn.SWITCH(Sheet5!A9,1,"JANUARY",2,"FEBRUARY")} -> JANUARY | E9: 7 | F9: {=_xlfn.SWITCH(Sheet5!C9,FALSE,"NO",TRUE,"YES")} -> NO | G9: {=_xlfn.SWITCH(Sheet5!B9,0,"Sunday",1,"Monday",2,"Tuesday",3,"Wednesday",4,"Thursday",5,"Friday",6,"Saturday")} -> Saturday | H9: {=_xlfn.SWITCH(Sheet5!D9, 1, "Clear Sky", 2, "Mist", 3, "Dark Cloud",4,"Heavy Rainfall")} -> Clear Sky | I9: =Sheet5!E9*41 -> 8.2 | J9: 0.86 | K9: 0 | L9: 1 | M9: 2 | N9: 3
A10: 9 | B10: 40544 | C10: winter | D10: {=_xlfn.SWITCH(Sheet5!A10,1,"JANUARY",2,"FEBRUARY")} -> JANUARY | E10: 8 | F10: {=_xlfn.SWITCH(Sheet5!C10,FALSE,"NO",TRUE,"YES")} -> NO | G10: {=_xlfn.SWITCH(Sheet5!B10,0,"Sunday",1,"Monday",2,"Tuesday",3,"Wednesday",4,"Thursday",5,"Friday",6,"Saturday")} -> Saturday | H10: {=_xlfn.SWITCH(Sheet5!D10, 1, "Clear Sky", 2, "Mist", 3, "Dark Cloud",4,"Heavy Rainfall")} -> Clear Sky | I10: =Sheet5!E10*41 -> 9.84 | J10: 0.75 | K10: 0 | L10: 1 | M10: 7 | N10: 8
A11: 10 | B11: 40544 | C11: winter | D11: {=_xlfn.SWITCH(Sheet5!A11,1,"JANUARY",2,"FEBRUARY")} -> JANUARY | E11: 9 | F11: {=_xlfn.SWITCH(Sheet5!C11,FALSE,"NO",TRUE,"YES")} -> NO | G11: {=_xlfn.SWITCH(Sheet5!B11,0,"Sunday",1,"Monday",2,"Tuesday",3,"Wednesday",4,"Thursday",5,"Friday",6,"Saturday")} -> Saturday | H11: {=_xlfn.SWITCH(Sheet5!D11, 1, "Clear Sky", 2, "Mist", 3, "Dark Cloud",4,"Heavy Rainfall")} -> Clear Sky | I11: =Sheet5!E11*41 -> 13.12 | J11: 0.76 | K11: 0 | L11: 8 | M11: 6 | N11: 14
A12: 11 | B12: 40544 | C12: winter | D12: {=_xlfn.SWITCH(Sheet5!A12,1,"JANUARY",2,"FEBRUARY")} -> JANUARY | E12: 10 | F12: {=_xlfn.SWITCH(Sheet5!C12,FALSE,"NO",TRUE,"YES")} -> NO | G12: {=_xlfn.SWITCH(Sheet5!B12,0,"Sunday",1,"Monday",2,"Tuesday",3,"Wednesday",4,"Thursday",5,"Friday",6,"Saturday")} -> Saturday | H12: {=_xlfn.SWITCH(Sheet5!D12, 1, "Clear Sky", 2, "Mist", 3, "Dark Cloud",4,"Heavy Rainfall")} -> Clear Sky | I12: =Sheet5!E12*41 -> 15.58 | J12: 0.76 | K12: 0.2537 | L12: 12 | M12: 24 | N12: 36
A13: 12 | B13: 40544 | C13: winter | D13: {=_xlfn.SWITCH(Sheet5!A13,1,"JANUARY",2,"FEBRUARY")} -> JANUARY | E13: 11 | F13: {=_xlfn.SWITCH(Sheet5!C13,FALSE,"NO",TRUE,"YES")} -> NO | G13: {=_xlfn.SWITCH(Sheet5!B13,0,"Sunday",1,"Monday",2,"Tuesday",3,"Wednesday",4,"Thursday",5,"Friday",6,"Saturday")} -> Saturday | H13: {=_xlfn.SWITCH(Sheet5!D13, 1, "Clear Sky", 2, "Mist", 3, "Dark Cloud",4,"Heavy Rainfall")} -> Clear Sky | I13: =Sheet5!E13*41 -> 14.76 | J13: 0.81 | K13: 0.2836 | L13: 26 | M13: 30 | N13: 56
... A1001: 1000 | B1001: 40588 | C1001: winter | D1001: {=_xlfn.SWITCH(Sheet5!A1001,1,"JANUARY",2,"FEBRUARY")} -> FEBRUARY | E1001: 7 | F1001: {=_xlfn.SWITCH(Sheet5!C1001,FALSE,"NO",TRUE,"YES")} -> NO | G1001: {=_xlfn.SWITCH(Sheet5!B1001,0,"Sunday",1,"Monday",2,"Tuesday",3,"Wednesday",4,"Thursday",5,"Friday",6,"Saturday")} -> Monday | H1001: {=_xlfn.SWITCH(Sheet5!D1001, 1, "Clear Sky", 2, "Mist", 3, "Dark Cloud",4,"Heavy Rainfall")} -> Clear Sky | I1001: =Sheet5!E1001*41 -> 13.94 | J1001: 0.46 | K1001: 0.2985 | L1001: 2 | M1001: 96 | N1001: 98
A1002: Total | N1002: =SUBTOTAL(109,Append1[cnt]) -> 58304

Sheet Dashboard
